Workbook

Sheet Plots

Sheet Failures
A1: Failure Date | B1: Failure Category | C1: Serial Number | D1: Additional Information
A2: 20/05/2025 | B2: Channel Undervoltage During Aging | C2: 190825130075 | D2: T=78c, CH3
A3: 20/05/2025 | B3: Setup Issue - AC | C3: 190825060204 | D3: Grid connected late
A4: 20/05/2025 | B4: Channel Short Circuit Before Aging | C4: 190824520068 | D4: CH4
A5: 23/05/2025 | B5: Channel Short Circuit During Aging | C5: 190825180078 | D5: T=88c, CH2
A6: 26/05/2025 | B6: Channel Short Circuit During Aging | C6: 190825180166 | D6: T=88c, CH1
A7: 26/05/2025 | B7: Setup Issue - AC | C7: 190825180056 | D7: Grid connected late
A8: 26/05/2025 | B8: Setup Issue - AC | C8: 190825180245 | D8: Grid connected late
A9: 26/05/2025 | B9: Setup Issue - AC | C9: 190825180149 | D9: Grid connected late
A10: 26/05/2025 | B10: Setup Issue - AC | C10: 190825180150 | D10: Grid connected late
A11: 28/05/2025 | B11: Channel Short Circuit Before Aging | C11: 190825180351 | D11: CH4
A12: 03/06/2025 | B12: Setup Issue - Mixed Connectors | C12: 190825180313
A13: 03/06/2025 | B13: Setup Issue - AC | C13: 190825180303 | D13: Grid connected late
A14: 03/06/2025 | B14: Setup Issue - DC | C14: 190825180201 | D14: ch1/ch2 0 volts
A15: 10/06/2025 | B15: Channel Undervoltage During Aging | C15: 190825180300 | D15: T=66c, CH1
A16: 23/06/2025 | B16: Channel Short Circuit During Aging | C16: 190825180328 | D16: T=88c, CH2
A17: 04/07/2025 | B17: Channel Short Circuit During Aging | C17: 190825250027 | D17: T=86c, CH3
A18: 06/07/2025 | B18: Channel Short Circuit During Aging | C18: 190825260094 | D18: T=85c, CH3
A19: 06/07/2025 | B19: Channel Short Circuit During Aging | C19: 190825250132 | D19: T=86c, CH1
A20: 07/07/2025 | B20: Channel Short Circuit During Aging | C20: 190825250124 | D20: T=82c, CH3
A21: 08/07/2025 | B21: Channel Short Circuit During Aging | C21: 190825260311 | D21: T=82c, CH1
A22: 08/07/2025 | B22: Setup Issue - DC | C22: 190825260250 | D22: PV4 Bad connection/source
A23: 09/07/2025 | B23: Inverter Failure During Burnin - Other | C23: 190825260022
A24: 10/07/2025 | B24: Channel Short Circuit During Aging | C24: 190825250014 | D24: T=86c, CH1
A25: 10/07/2025 | B25: Channel Short Circuit During Aging | C25: 190825250098 | D25: T=84c, CH4
A26: 10/07/2025 | B26: Channel Short Circuit During Aging | C26: 190825260388 | D26: T=87c, CH2
A27: 14/07/2025 | B27: Channel Short Circuit During Aging | C27: 190825260198 | D27: T=91c, CH3
A28: 14/07/2025 | B28: Setup Issue - Mixed Connectors | C28: 190825260289
A29: 14/07/2025 | B29: Channel Short Circuit During Aging | C29: 190825260238 | D29: T=90c, CH4
A30: 14/07/2025 | B30: Channel Short Circuit During Aging | C30: 190825260257 | D30: T=90c, CH1 intermittent failure
A31: 15/07/2025 | B31: Channel Short Circuit During Aging | C31: 190825260252 | D31: T=77c, CH4
A32: 17/07/2025 | B32: GFDI Fault | C32: 190825260626
A33: 17/07/2025 | B33: GFDI Fault | C33: 190825260206
A34: 18/07/2025 | B34: Setup Issue - Mixed Connectors | C34: 190825260753
A35: 18/07/2025 | B35: Setup Issue - Mixed Connectors | C35: 190825260754
A36: 18/07/2025 | B36: Channel Short Circuit During Aging | C36: 190825260074 | D36: T=85c, CH3
A37: 18/07/2025 | B37: Channel Short Circuit During Aging | C37: 190825260336 | D37: T=91c, CH1
A38: 19/07/2025 | B38: Channel Short Circuit Before Aging | C38: 190825260489 | D38: CH1
A39: 20/07/2025 | B39: Channel Short Circuit Before Aging | C39: 190825260628 | D39: CH2
A40: 20/07/2025 | B40: GFDI Fault | C40: 190825260206
...

Sheet failure_mode_incidence_counts
A1: Period | B1: Channel Short Circuit Before Aging | C1: Channel Short Circuit During Aging | D1: Channel Undervoltage Before Aging | E1: Channel Undervoltage During Aging | F1: GFDI Fault | G1: Inverter Failure During Burnin - Other | H1: Setup Issue - AC | I1: Setup Issue - DC | J1: Setup Issue - Mixed Connectors
A2: May | B2: 2 | C2: 2 | E2: 1 | H2: 5
A3: June | C3: 1 | E3: 1 | H3: 1 | I3: 1 | J3: 1
A4: July | B4: 2 | C4: 17 | D4: 1 | E4: 1 | F4: 5 | G4: 3 | I4: 13 | J4: 5
A5: Total | B5: =SUM(B2:B4) -> 4 | C5: =SUM(C2:C4) -> 20 | D5: =SUM(D2:D4) -> 1 | E5: =SUM(E2:E4) -> 3 | F5: =SUM(F2:F4) -> 5 | G5: =SUM(G2:G4) -> 3 | H5: =SUM(H2:H4) -> 6 | I5: =SUM(I2:I4) -> 14 | J5: =SUM(J2:J4) -> 6
A8: setup/manufacturing/gfdi | B8: =B5+D5+F5+H5+I5+J5 -> 36
A9: High temperature DC failure during burnin | B9: =C5+E5 -> 23
A10: Other failure during burnin | B10: =G5 -> 3
B15: CH1 | C15: CH2 | D15: CH3 | E15: CH4
A16: DC Failures by Channel | B16: 10 | C16: 9 | D16: 7 | E16: 5

Sheet failure_mode_percentages
A1: Period | B1: Channel Short Circuit Before Aging | C1: Channel Short Circuit During Aging | D1: Channel Undervoltage Before Aging | E1: Channel Undervoltage During Aging | F1: GFDI Fault | G1: Inverter Failure During Burnin - Other | H1: Setup Issue - AC | I1: Setup Issue - DC | J1: Setup Issue - Mixed Connectors | L1: Total Tests
A2: May | B2: =failure_mode_incidence_counts!B2/$L2*100 -> 0.61919505 | C2: =failure_mode_incidence_counts!C2/$L2*100 -> 0.61919505 | D2: =failure_mode_incidence_counts!D2/$L2*100 -> 0 | E2: =failure_mode_incidence_counts!E2/$L2*100 -> 0.30959752 | F2: =failure_mode_incidence_counts!F2/$L2*100 -> 0 | G2: =failure_mode_incidence_counts!G2/$L2*100 -> 0 | H2: =failure_mode_incidence_counts!H2/$L2*100 -> 1.5479876 | I2: =failure_mode_incidence_counts!I2/$L2*100 -> 0 | J2: =failure_mode_incidence_counts!J2/$L2*100 -> 0 | L2: 323
A3: June | B3: =failure_mode_incidence_counts!B3/$L3*100 -> 0 | C3: =failure_mode_incidence_counts!C3/$L3*100 -> 0.68493151 | D3: =failure_mode_incidence_counts!D3/$L3*100 -> 0 | E3: =failure_mode_incidence_counts!E3/$L3*100 -> 0.68493151 | F3: =failure_mode_incidence_counts!F3/$L3*100 -> 0 | G3: =failure_mode_incidence_counts!G3/$L3*100 -> 0 | H3: =failure_mode_incidence_counts!H3/$L3*100 -> 0.68493151 | I3: =failure_mode_incidence_counts!I3/$L3*100 -> 0.68493151 | J3: =failure_mode_incidence_counts!J3/$L3*100 -> 0.68493151 | L3: 146
A4: July | B4: =failure_mode_incidence_counts!B4/$L4*100 -> 0.20597322 | C4: =failure_mode_incidence_counts!C4/$L4*100 -> 1.7507724 | D4: =failure_mode_incidence_counts!D4/$L4*100 -> 0.10298661 | E4: =failure_mode_incidence_counts!E4/$L4*100 -> 0.10298661 | F4: =failure_mode_incidence_counts!F4/$L4*100 -> 0.51493306 | G4: =failure_mode_incidence_counts!G4/$L4*100 -> 0.30895984 | H4: =failure_mode_incidence_counts!H4/$L4*100 -> 0 | I4: =failure_mode_incidence_counts!I4/$L4*100 -> 1.338826 | J4: =failure_mode_incidence_counts!J4/$L4*100 -> 0.51493306 | L4: 971
A7: failure due to | B7: percent of tests
A8: Setup/manufacturing/gfdi | B8: =failure_mode_incidence_counts!B8/SUM(L2:L4)*100 -> 2.5
A9: High temperature DC failure during burnin | B9: =failure_mode_incidence_counts!B9/SUM(L2:L4)*100 -> 1.5972222
A10: Other failure during burnin | B10: =failure_mode_incidence_counts!B10/SUM(L2:L4)*100 -> 0.20833333
